Workbook

Sheet Campaign Data
A1: Campaign_Name | B1: Start_Date | C1: End_Date | D1: Objective | E1: Total_Budget | F1: Target_Platforms
A2: EndOfSeasonSale | B2: 45453 | C2: 45478 | D2: Seasonal Clearance Promotion | E2: 180000 | F2: Instagram,Facebook
A3: FashionUpgrade | B3: 45505 | C3: 45535 | D3: Customer Engagement | E3: 160000 | F3: Instagram,YouTube
A4: MyntraFestiveEdit | B4: 45570 | C4: 45601 | D4: Festive Collection Launch | E4: 220000 | F4: Facebook,Instagram
A5: StyleRevolution | B5: 45667 | C5: 45698 | D5: Brand Awareness & Growth | E5: 200000 | F5: Instagram,Twitter

Sheet Post
A1: Post ID | B1: Platform | C1: Date | D1: Content Type | E1: Post Text | F1: Likes | G1: Shares | H1: Comments | I1: Engagement | J1: Engagement Average | K1: Impressions | L1: Reach | M1: Clicks | N1: Hashtags Used | O1: Hashtags Used 2 | P1: Campaign_Name | Q1: Ad_Spend | R1: Net_Growth | S1: ROI | T1: Campaign_Name | U1: during campign | V1: Before campign | W1: uplift
A2: P001 | B2: Twitter | C2: 45649 | D2: Reel | E2: Explore the latest reel on Myntra! Trendy styles await. | F2: 1461 | G2: 184 | H2: 344 | I2: =SUM(F2+G2+H2) -> 1989 | J2: =(F2+G2+H2)/K2 -> 0.090759754 | K2: 21915 | L2: 21675 | M2: 15 | N2: #MyntraSale | P2: FashionUpgrade | Q2: 5904 | R2: 1047 | S2: =I2/Q2 -> 0.33689024 | T2: EndOfSeasonSale | U2: 20185 | V2: 18337 | W2: =SUM(U2-V2)/V2 -> 0.10077984
A3: P002 | B3: Twitter | C3: 45750 | D3: Text | E3: Explore the latest text on Myntra! Trendy styles await. | F3: 4054 | G3: 389 | H3: 493 | I3: =SUM(F3+G3+H3) -> 4936 | J3: =(F3+G3+H3)/K3 -> 0.076097681 | K3: 64864 | L3: 64383 | M3: 117 | N3: #MyntraFashion | P3: EndOfSeasonSale | Q3: 9566 | R3: 1002 | S3: =I3/Q3 -> 0.51599415 | T3: FashionUpgrade | U3: 29029 | V3: 67773 | W3: =SUM(U3-V3)/V3 -> -0.57167309
A4: P003 | B4: YouTube | C4: 45789 | D4: Reel | E4: Explore the latest reel on Myntra! Trendy styles await. | F4: 2795 | G4: 105 | H4: 49 | I4: =SUM(F4+G4+H4) -> 2949 | J4: =(F4+G4+H4)/K4 -> 0.055531494 | K4: 53105 | L4: 52307 | M4: 204 | N4: #MyntraFashion | O4: #MyntraSale | P4: FashionUpgrade | Q4: 26752 | R4: 415 | S4: =I4/Q4 -> 0.11023475 | T4: MyntraFestiveEdit | U4: 25499 | V4: 95022 | W4: =SUM(U4-V4)/V4 -> -0.73165162
A5: P004 | B5: Instagram | C5: 45516 | D5: Story | E5: Explore the latest story on Myntra! Trendy styles await. | F5: 2404 | G5: 363 | H5: 138 | I5: =SUM(F5+G5+H5) -> 2905 | J5: =(F5+G5+H5)/K5 -> 0.15105033 | K5: 19232 | L5: 18636 | M5: 128 | N5: #MyntraSale | P5: FashionUpgrade | Q5: 30671 | R5: 1090 | S5: =I5/Q5 -> 0.094714877 | T5: StyleRevolution | U5: 16716 | V5: 133833 | W5: =SUM(U5-V5)/V5 -> -0.87509807
A6: P005 | B6: YouTube | C6: 45469 | D6: Reel | E6: Explore the latest reel on Myntra! Trendy styles await. | F6: 3557 | G6: 687 | H6: 424 | I6: =SUM(F6+G6+H6) -> 4668 | J6: =(F6+G6+H6)/K6 -> 0.065617093 | K6: 71140 | L6: 70701 | M6: 224 | N6: #StyleWithMyntra | O6: #MyntraFashion | P6: MyntraFestiveEdit | Q6: 9920 | R6: 517 | S6: =I6/Q6 -> 0.47056452
A7: P006 | B7: Facebook | C7: 45596 | D7: Carousel | E7: Explore the latest carousel on Myntra! Trendy styles await. | F7: 2945 | G7: 930 | H7: 355 | I7: =SUM(F7+G7+H7) -> 4230 | J7: =(F7+G7+H7)/K7 -> 0.1795416 | K7: 23560 | L7: 23275 | M7: 256 | N7: #MyntraTrend | P7: EndOfSeasonSale | Q7: 7924 | R7: 1283 | S7: =I7/Q7 -> 0.5338213
A8: P007 | B8: Twitter | C8: 45467 | D8: Carousel | E8: Explore the latest carousel on Myntra! Trendy styles await. | F8: 3860 | G8: 201 | H8: 279 | I8: =SUM(F8+G8+H8) -> 4340 | J8: =(F8+G8+H8)/K8 -> 0.070272021 | K8: 61760 | L8: 61660 | M8: 235 | N8: #MyntraTrend | P8: MyntraFestiveEdit | Q8: 8912 | R8: 186 | S8: =I8/Q8 -> 0.48698384
A9: P008 | B9: YouTube | C9: 45486 | D9: Image | E9: Explore the latest image on Myntra! Trendy styles await. | F9: 3929 | G9: 262 | H9: 278 | I9: =SUM(F9+G9+H9) -> 4469 | J9: =(F9+G9+H9)/K9 -> 0.1034036 | K9: 43219 | L9: 42841 | M9: 39 | N9: #MyntraFashion | O9: #MyntraSale | P9: MyntraFestiveEdit | Q9: 21205 | R9: 994 | S9: =I9/Q9 -> 0.21075218
A10: P009 | B10: Facebook | C10: 45534 | D10: Text | E10: Explore the latest text on Myntra! Trendy styles await. | F10: 3784 | G10: 808 | H10: 404 | I10: =SUM(F10+G10+H10) -> 4996 | J10: =(F10+G10+H10)/K10 -> 0.088019732 | K10: 56760 | L10: 56343 | M10: 131 | N10: #MyntraFashion | O10: #MyntraSale | P10: MyntraFestiveEdit | Q10: 11329 | R10: 893 | S10: =I10/Q10 -> 0.44099214
A11: P010 | B11: Facebook | C11: 45727 | D11: Image | E11: Explore the latest image on Myntra! Trendy styles await. | F11: 4241 | G11: 902 | H11: 47 | I11: =SUM(F11+G11+H11) -> 5190 | J11: =(F11+G11+H11)/K11 -> 0.071986352 | K11: 72097 | L11: 71598 | M11: 167 | N11: #MyntraTrend | P11: StyleRevolution | Q11: 46670 | R11: 1382 | S11: =I11/Q11 -> 0.11120634 | AA11: Total & Average Impressions, Likes, Clicks per Campaign.
A12: P011 | B12: Instagram | C12: 45690 | D12: Story | E12: Explore the latest story on Myntra! Trendy styles await. | F12: 1792 | G12: 614 | H12: 497 | I12: =SUM(F12+G12+H12) -> 2903 | J12: =(F12+G12+H12)/K12 -> 0.11571269 | K12: 25088 | L12: 24675 | M12: 65 | N12: #StyleWithMyntra | P12: FashionUpgrade | Q12: 22482 | R12: 1295 | S12: =I12/Q12 -> 0.12912552
A13: P012 | B13: Facebook | C13: 45494 | D13: Reel | E13: Explore the latest reel on Myntra! Trendy styles await. | F13: 1946 | G13: 686 | H13: 377 | I13: =SUM(F13+G13+H13) -> 3009 | J13: =(F13+G13+H13)/K13 -> 0.12885406 | K13: 23352 | L13: 22982 | M13: 213 | N13: #StyleWithMyntra | O13: #MyntraSale | P13: MyntraFestiveEdit | Q13: 24313 | R13: 337 | S13: =I13/Q13 -> 0.12376095
A14: P013 | B14: YouTube | C14: 45614 | D14: Carousel | E14: Explore the latest carousel on Myntra! Trendy styles await. | F14: 1171 | G14: 286 | H14: 231 | I14: =SUM(F14+G14+H14) -> 1688 | J14: =(F14+G14+H14)/K14 -> 0.075868578 | K14: 22249 | L14: 21282 | M14: 114 | N14: #MyntraFashion | P14: StyleRevolution | Q14: 18050 | R14: 629 | S14: =I14/Q14 -> 0.093518006
A15: P014 | B15: Facebook | C15: 45704 | D15: Story | E15: Explore the latest story on Myntra! Trendy styles await. | F15: 4242 | G15: 555 | H15: 131 | I15: =SUM(F15+G15+H15) -> 4928 | J15: =(F15+G15+H15)/K15 -> 0.14521452 | K15: 33936 | L15: 33802 | M15: 265 | N15: #MyntraSale | O15: #MyntraFashion | P15: MyntraFestiveEdit | Q15: 30635 | R15: 1670 | S15: =I15/Q15 -> 0.16086176
A16: P015 | B16: Facebook | C16: 45589 | D16: Video | E16: Explore the latest video on Myntra! Trendy styles await. | F16: 3888 | G16: 604 | H16: 128 | I16: =SUM(F16+G16+H16) -> 4620 | J16: =(F16+G16+H16)/K16 -> 0.05941358 | K16: 77760 | L16: 77167 | M16: 20 | N16: #MyntraFashion | O16: #FashionDeals | P16: FashionUpgrade | Q16: 31280 | R16: 835 | S16: =I16/Q16 -> 0.14769821
A17: P016 | B17: Facebook | C17: 45530 | D17: Text | E17: Explore the latest text on Myntra! Trendy styles await. | F17: 3452 | G17: 377 | H17: 360 | I17: =SUM(F17+G17+H17) -> 4189 | J17: =(F17+G17+H17)/K17 -> 0.075843714 | K17: 55232 | L17: 55075 | M17: 87 | N17: #MyntraSale | O17: #FashionDeals | P17: MyntraFestiveEdit | Q17: 1783 | R17: -123 | S17: =I17/Q17 -> 2.3494111
A18: P017 | B18: Facebook | C18: 45782 | D18: Text | E18: Explore the latest text on Myntra! Trendy styles await. | F18: 4441 | G18: 511 | H18: 70 | I18: =SUM(F18+G18+H18) -> 5022 | J18: =(F18+G18+H18)/K18 -> 0.094235533 | K18: 53292 | L18: 53082 | M18: 159 | N18: #FashionDeals | P18: MyntraFestiveEdit | Q18: 9566 | R18: -219 | S18: =I18/Q18 -> 0.52498432
A19: P018 | B19: Instagram | C19: 45523 | D19: Reel | E19: Explore the latest reel on Myntra! Trendy styles await. | F19: 3000 | G19: 382 | H19: 325 | I19: =SUM(F19+G19+H19) -> 3707 | J19: =(F19+G19+H19)/K19 -> 0.10297222 | K19: 36000 | L19: 35819 | M19: 19 | N19: #StyleWithMyntra | P19: EndOfSeasonSale | Q19: 42307 | R19: 64 | S19: =I19/Q19 -> 0.087621434
A20: P019 | B20: Instagram | C20: 45466 | D20: Video | E20: Explore the latest video on Myntra! Trendy styles await. | F20: 1071 | G20: 519 | H20: 22 | I20: =SUM(F20+G20+H20) -> 1612 | J20: =(F20+G20+H20)/K20 -> 0.10034236 | K20: 16065 | L20: 15865 | M20: 103 | N20: #MyntraSale | O20: #StyleWithMyntra | P20: MyntraFestiveEdit | Q20: 5914 | R20: 1357 | S20: =I20/Q20 -> 0.27257355
A21: P020 | B21: Instagram | C21: 45544 | D21: Carousel | E21: Explore the latest carousel on Myntra! Trendy styles await. | F21: 4054 | G21: 488 | H21: 373 | I21: =SUM(F21+G21+H21) -> 4915 | J21: =(F21+G21+H21)/K21 -> 0.063809623 | K21: 77026 | L21: 76881 | M21: 25 | N21: #MyntraFashion | O21: #MyntraSale | P21: MyntraFestiveEdit | Q21: 30060 | R21: 91 | S21: =I21/Q21 -> 0.16350632
A22: P021 | B22: Instagram | C22: 45661 | D22: Reel | E22: Explore the latest reel on Myntra! Trendy styles await. | F22: 4838 | G22: 640 | H22: 128 | I22: =SUM(F22+G22+H22) -> 5606 | J22: =(F22+G22+H22)/K22 -> 0.077249552 | K22: 72570 | L22: 72396 | M22: 83 | N22: #StyleWithMyntra | O22: #MyntraTrend | P22: MyntraFestiveEdit | Q22: 22728 | R22: 1672 | S22: =I22/Q22 -> 0.24665611
A23: P022 | B23: Facebook | C23: 45715 | D23: Text | E23: Explore the latest text on Myntra! Trendy styles await. | F23: 1570 | G23: 187 | H23: 260 | I23: =SUM(F23+G23+H23) -> 2017 | J23: =(F23+G23+H23)/K23 -> 0.080294586 | K23: 25120 | L23: 24613 | M23: 133 | N23: #MyntraSale | P23: StyleRevolution | Q23: 38610 | R23: 309 | S23: =I23/Q23 -> 0.052240352
A24: P023 | B24: Facebook | C24: 45602 | D24: Video | E24: Explore the latest video on Myntra! Trendy styles await. | F24: 1606 | G24: 547 | H24: 316 | I24: =SUM(F24+G24+H24) -> 2469 | J24: =(F24+G24+H24)/K24 -> 0.076867995 | K24: 32120 | L24: 31736 | M24: 225 | N24: #MyntraSale | P24: MyntraFestiveEdit | Q24: 2932 | R24: 547 | S24: =I24/Q24 -> 0.84208731
A25: P024 | B25: Facebook | C25: 45680 | D25: Video | E25: Explore the latest video on Myntra! Trendy styles await. | F25: 3961 | G25: 761 | H25: 131 | I25: =SUM(F25+G25+H25) -> 4853 | J25: =(F25+G25+H25)/K25 -> 0.072070333 | K25: 67337 | L25: 66615 | M25: 161 | N25: #MyntraTrend | P25: EndOfSeasonSale | Q25: 15071 | R25: 514 | S25: =I25/Q25 -> 0.32200916 | W25: Row Labels | X25: Sum of Clicks | Y25: Sum of Impressions | Z25: Sum of Likes | AA25: Average of Clicks2 | AB25: Average of Impressions2 | AC25: Average of Likes2
A26: P025 | B26: Twitter | C26: 45757 | D26: Carousel | E26: Explore the latest carousel on Myntra! Trendy styles await. | F26: 3128 | G26: 211 | H26: 197 | I26: =SUM(F26+G26+H26) -> 3536 | J26: =(F26+G26+H26)/K26 -> 0.059496568 | K26: 59432 | L26: 59182 | M26: 238 | N26: #StyleWithMyntra | O26: #MyntraSale | P26: FashionUpgrade | Q26: 10740 | R26: 1845 | S26: =I26/Q26 -> 0.3292365 | W26: EndOfSeasonSale | X26: 12376 | Y26: 2886292 | Z26: 232785 | AA26: 149.10843 | AB26: 34774.602 | AC26: 2804.6386
A27: P026 | B27: YouTube | C27: 45752 | D27: Reel | E27: Explore the latest reel on Myntra! Trendy styles await. | F27: 3009 | G27: 413 | H27: 358 | I27: =SUM(F27+G27+H27) -> 3780 | J27: =(F27+G27+H27)/K27 -> 0.089730808 | K27: 42126 | L27: 41309 | M27: 211 | N27: #MyntraSale | P27: EndOfSeasonSale | Q27: 43420 | R27: -164 | S27: =I27/Q27 -> 0.087056656 | W27: FashionUpgrade | X27: 11191 | Y27: 2788367 | Z27: 212431 | AA27: 155.43056 | AB27: 38727.319 | AC27: 2950.4306
A28: P027 | B28: YouTube | C28: 45552 | D28: Text | E28: Explore the latest text on Myntra! Trendy styles await. | F28: 2076 | G28: 195 | H28: 104 | I28: =SUM(F28+G28+H28) -> 2375 | J28: =(F28+G28+H28)/K28 -> 0.071501686 | K28: 33216 | L28: 32244 | M28: 51 | N28: #MyntraTrend | P28: StyleRevolution | Q28: 32393 | R28: 429 | S28: =I28/Q28 -> 0.07331831 | W28: MyntraFestiveEdit | X28: 12464 | Y28: 2611652 | Z28: 198666 | AA28: 159.79487 | AB28: 33482.718 | AC28: 2547
A29: P028 | B29: Instagram | C29: 45720 | D29: Video | E29: Explore the latest video on Myntra! Trendy styles await. | F29: 432 | G29: 624 | H29: 123 | I29: =SUM(F29+G29+H29) -> 1179 | J29: =(F29+G29+H29)/K29 -> 0.17057292 | K29: 6912 | L29: 6259 | M29: 79 | N29: #MyntraSale | O29: #MyntraTrend | P29: EndOfSeasonSale | Q29: 28474 | R29: 160 | S29: =I29/Q29 -> 0.041406195 | W29: StyleRevolution | X29: 9335 | Y29: 2107842 | Z29: 176109 | AA29: 139.32836 | AB29: 31460.328 | AC29: 2628.4925
A30: P029 | B30: Instagram | C30: 45688 | D30: Carousel | E30: Explore the latest carousel on Myntra! Trendy styles await. | F30: 2566 | G30: 118 | H30: 37 | I30: =SUM(F30+G30+H30) -> 2721 | J30: =(F30+G30+H30)/K30 -> 0.21208106 | K30: 12830 | L30: 12264 | M30: 221 | N30: #MyntraTrend | O30: #MyntraFashion | P30: MyntraFestiveEdit | Q30: 17328 | R30: 159 | S30: =I30/Q30 -> 0.15702909 | W30: Grand Total | X30: 45366 | Y30: 10394153 | Z30: 819991 | AA30: 151.22 | AB30: 34647.177 | AC30: 2733.3033
A31: P030 | B31: Instagram | C31: 45713 | D31: Video | E31: Explore the latest video on Myntra! Trendy styles await. | F31: 3095 | G31: 39 | H31: 78 | I31: =SUM(F31+G31+H31) -> 3212 | J31: =(F31+G31+H31)/K31 -> 0.057655717 | K31: 55710 | L31: 54808 | M31: 93 | N31: #MyntraSale | P31: StyleRevolution | Q31: 26067 | R31: 961 | S31: =I31/Q31 -> 0.12322093
A32: P031 | B32: Instagram | C32: 45642 | D32: Text | E32: Explore the latest text on Myntra! Trendy styles await. | F32: 438 | G32: 153 | H32: 275 | I32: =SUM(F32+G32+H32) -> 866 | J32: =(F32+G32+H32)/K32 -> 0.28245271 | K32: 3066 | L32: 2701 | M32: 282 | N32: #MyntraTrend | P32: StyleRevolution | Q32: 32763 | R32: 1316 | S32: =I32/Q32 -> 0.026432256
A33: P032 | B33: Twitter | C33: 45504 | D33: Carousel | E33: Explore the latest carousel on Myntra! Trendy styles await. | F33: 2278 | G33: 10 | H33: 321 | I33: =SUM(F33+G33+H33) -> 2609 | J33: =(F33+G33+H33)/K33 -> 0.19088382 | K33: 13668 | L33: 12676 | M33: 275 | N33: #MyntraTrend | O33: #MyntraFashion | P33: StyleRevolution | Q33: 26452 | R33: 317 | S33: =I33/Q33 -> 0.098631483
A34: P033 | B34: Facebook | C34: 45525 | D34: Image | E34: Explore the latest image on Myntra! Trendy styles await. | F34: 1407 | G34: 400 | H34: 351 | I34: =SUM(F34+G34+H34) -> 2158 | J34: =(F34+G34+H34)/K34 -> 0.12781331 | K34: 16884 | L34: 15954 | M34: 113 | N34: #MyntraFashion | O34: #FashionDeals | P34: MyntraFestiveEdit | Q34: 15353 | R34: 541 | S34: =I34/Q34 -> 0.14055885
A35: P034 | B35: Facebook | C35: 45742 | D35: Text | E35: Explore the latest text on Myntra! Trendy styles await. | F35: 1652 | G35: 89 | H35: 357 | I35: =SUM(F35+G35+H35) -> 2098 | J35: =(F35+G35+H35)/K35 -> 0.07055421 | K35: 29736 | L35: 28771 | M35: 215 | N35: #MyntraTrend | O35: #FashionDeals | P35: EndOfSeasonSale | Q35: 4839 | R35: -318 | S35: =I35/Q35 -> 0.43356065
A36: P035 | B36: Instagram | C36: 45626 | D36: Video | E36: Explore the latest video on Myntra! Trendy styles await. | F36: 3775 | G36: 16 | H36: 239 | I36: =SUM(F36+G36+H36) -> 4030 | J36: =(F36+G36+H36)/K36 -> 0.11861663 | K36: 33975 | L36: 33310 | M36: 271 | N36: #StyleWithMyntra | O36: #MyntraSale | P36: MyntraFestiveEdit | Q36: 39272 | R36: 1495 | S36: =I36/Q36 -> 0.10261764
A37: P036 | B37: Instagram | C37: 45766 | D37: Story | E37: Explore the latest story on Myntra! Trendy styles await. | F37: 4518 | G37: 285 | H37: 383 | I37: =SUM(F37+G37+H37) -> 5186 | J37: =(F37+G37+H37)/K37 -> 0.076523535 | K37: 67770 | L37: 67621 | M37: 31 | N37: #FashionDeals | P37: EndOfSeasonSale | Q37: 16804 | R37: 475 | S37: =I37/Q37 -> 0.308617
A38: P037 | B38: Facebook | C38: 45663 | D38: Carousel | E38: Explore the latest carousel on Myntra! Trendy styles await. | F38: 3024 | G38: 925 | H38: 350 | I38: =SUM(F38+G38+H38) -> 4299 | J38: =(F38+G38+H38)/K38 -> 0.17770337 | K38: 24192 | L38: 23518 | M38: 36 | N38: #MyntraSale | P38: MyntraFestiveEdit | Q38: 49303 | R38: 352 | S38: =I38/Q38 -> 0.087195505
A39: P038 | B39: YouTube | C39: 45705 | D39: Reel | E39: Explore the latest reel on Myntra! Trendy styles await. | F39: 3138 | G39: 123 | H39: 291 | I39: =SUM(F39+G39+H39) -> 3552 | J39: =(F39+G39+H39)/K39 -> 0.12577013 | K39: 28242 | L39: 27550 | M39: 87 | N39: #FashionDeals | P39: StyleRevolution | Q39: 26455 | R39: -197 | S39: =I39/Q39 -> 0.13426573
A40: P039 | B40: Facebook | C40: 45621 | D40: Image | E40: Explore the latest image on Myntra! Trendy styles await. | F40: 3564 | G40: 629 | H40: 177 | I40: =SUM(F40+G40+H40) -> 4370 | J40: =(F40+G40+H40)/K40 -> 0.072126494 | K40: 60588 | L40: 59627 | M40: 92 | N40: #FashionDeals | O40: #MyntraSale | P40: MyntraFestiveEdit | Q40: 12384 | R40: 328 | S40: =I40/Q40 -> 0.35287468
...

Sheet Engagment Summary
A1: Week_Start_Date | B1: Platform | C1: New_Followers | D1: Unfollows | E1: Net_Growth | F1: growth rate | G1: Total_Followers | H1: Engagement_Rate | I1: Ad_Spend | J1: =Post!I1 -> Engagement
A2: 45446 | B2: Instagram | C2: 1135 | D2: 88 | E2: =C2-D2 -> 1047 | F2: =(C2-D2)/(G2-(C2-D2)) -> 0.0030521489 | G2: 344084 | H2: 8.06 | I2: 5904 | J2: =Post!I2 -> 1989
A3: 45446 | B3: Facebook | C3: 1312 | D3: 310 | E3: =C3-D3 -> 1002 | F3: =(C3-D3)/(G3-(C3-D3)) -> 0.024056468 | G3: 42654 | H3: 4.98 | I3: 9566 | J3: =Post!I3 -> 4936
A4: 45446 | B4: Twitter | C4: 584 | D4: 169 | E4: =C4-D4 -> 415 | F4: =(C4-D4)/(G4-(C4-D4)) -> 0.0028343316 | G4: 146834 | H4: 8.31 | I4: 26752 | J4: =Post!I4 -> 2949
A5: 45446 | B5: YouTube | C5: 1535 | D5: 445 | E5: =C5-D5 -> 1090 | F5: =(C5-D5)/(G5-(C5-D5)) -> 0.0027633694 | G5: 395536 | H5: 4.11 | I5: 30671 | J5: =Post!I5 -> 2905
A6: 45453 | B6: Instagram | C6: 656 | D6: 139 | E6: =C6-D6 -> 517 | F6: =(C6-D6)/(G6-(C6-D6)) -> 0.010629112 | G6: 49157 | H6: 9.05 | I6: 9920 | J6: =Post!I6 -> 4668
A7: 45453 | B7: Facebook | C7: 1697 | D7: 414 | E7: =C7-D7 -> 1283 | F7: =(C7-D7)/(G7-(C7-D7)) -> 0.0040695019 | G7: 316555 | H7: 2.37 | I7: 7924 | J7: =Post!I7 -> 4230
A8: 45453 | B8: Twitter | C8: 436 | D8: 250 | E8: =C8-D8 -> 186 | F8: =(C8-D8)/(G8-(C8-D8)) -> 0.00073181959 | G8: 254347 | H8: 4.01 | I8: 8912 | J8: =Post!I8 -> 4340
A9: 45453 | B9: YouTube | C9: 1197 | D9: 203 | E9: =C9-D9 -> 994 | F9: =(C9-D9)/(G9-(C9-D9)) -> 0.0024074558 | G9: 413878 | H9: 3.16 | I9: 21205 | J9: =Post!I9 -> 4469
A10: 45460 | B10: Instagram | C10: 1048 | D10: 155 | E10: =C10-D10 -> 893 | F10: =(C10-D10)/(G10-(C10-D10)) -> 0.0019581057 | G10: 456946 | H10: 2.46 | I10: 11329 | J10: =Post!I10 -> 4996
A11: 45460 | B11: Facebook | C11: 1753 | D11: 371 | E11: =C11-D11 -> 1382 | F11: =(C11-D11)/(G11-(C11-D11)) -> 0.0082206122 | G11: 169496 | H11: 8.11 | I11: 46670 | J11: =Post!I11 -> 5190
A12: 45460 | B12: Twitter | C12: 1335 | D12: 40 | E12: =C12-D12 -> 1295 | F12: =(C12-D12)/(G12-(C12-D12)) -> 0.010663966 | G12: 122732 | H12: 8.19 | I12: 22482 | J12: =Post!I12 -> 2903
A13: 45460 | B13: YouTube | C13: 403 | D13: 66 | E13: =C13-D13 -> 337 | F13: =(C13-D13)/(G13-(C13-D13)) -> 0.00088101351 | G13: 382851 | H13: 3.49 | I13: 24313 | J13: =Post!I13 -> 3009
... A201: 45789 | B201: YouTube | C201: 119 | D201: 456 | E201: =C201-D201 -> -337 | F201: =(C201-D201)/(G201-(C201-D201)) -> -0.0040653839 | G201: 82558 | H201: 6.81 | I201: 12174 | J201: =Post!I201 -> 4413
